/mnt/disks/data/env/lib/python3.10/site-packages/torch/distributed/launch.py:180: FutureWarning: The module torch.distributed.launch is deprecated
and will be removed in future. Use torchrun.
Note that --use_env is set by default in torchrun.
If your script expects `--local_rank` argument to be set, please
change it to read from `os.environ['LOCAL_RANK']` instead. See 
https://pytorch.org/docs/stable/distributed.html#launch-utility for 
further instructions

  warnings.warn(
WARNING:torch.distributed.run:
*****************************************
Setting OMP_NUM_THREADS environment variable for each process to be 1 in default, to avoid your system being overloaded, please further tune the variable for optimal performance in your application as needed. 
*****************************************
Traceback (most recent call last):
  File "/mnt/disks/data/TecoGAN/./codes/main.py", line 335, in <module>
    opt = base_utils.parse_configs(args)
  File "/mnt/disks/data/TecoGAN/codes/utils/base_utils.py", line 43, in parse_configs
    setup_device(opt, args.gpu_ids, args.local_rank)
  File "/mnt/disks/data/TecoGAN/codes/utils/base_utils.py", line 72, in setup_device
    init_dist(opt, local_rank)
  File "/mnt/disks/data/TecoGAN/codes/utils/dist_utils.py", line 13, in init_dist
    torch.cuda.set_device(local_rank)
  File "/mnt/disks/data/env/lib/python3.10/site-packages/torch/cuda/__init__.py", line 326, in set_device
    torch._C._cuda_setDevice(device)
RuntimeError: CUDA error: invalid device ordinal
CUDA kernel errors might be asynchronously reported at some other API call,so the stacktrace below might be incorrect.
For debugging consider passing CUDA_LAUNCH_BLOCKING=1.
WARNING:torch.distributed.elastic.multiprocessing.api:Sending process 1974123 closing signal SIGTERM
ERROR:torch.distributed.elastic.multiprocessing.api:failed (exitcode: 1) local_rank: 1 (pid: 1974124) of binary: /mnt/disks/data/env/bin/python
Traceback (most recent call last):
  File "/opt/conda/lib/python3.10/runpy.py", line 196, in _run_module_as_main
    return _run_code(code, main_globals, None,
  File "/opt/conda/lib/python3.10/runpy.py", line 86, in _run_code
    exec(code, run_globals)
  File "/mnt/disks/data/env/lib/python3.10/site-packages/torch/distributed/launch.py", line 195, in <module>
    main()
  File "/mnt/disks/data/env/lib/python3.10/site-packages/torch/distributed/launch.py", line 191, in main
    launch(args)
  File "/mnt/disks/data/env/lib/python3.10/site-packages/torch/distributed/launch.py", line 176, in launch
    run(args)
  File "/mnt/disks/data/env/lib/python3.10/site-packages/torch/distributed/run.py", line 753, in run
    elastic_launch(
  File "/mnt/disks/data/env/lib/python3.10/site-packages/torch/distributed/launcher/api.py", line 132, in __call__
    return launch_agent(self._config, self._entrypoint, list(args))
  File "/mnt/disks/data/env/lib/python3.10/site-packages/torch/distributed/launcher/api.py", line 246, in launch_agent
    raise ChildFailedError(
torch.distributed.elastic.multiprocessing.errors.ChildFailedError: 
============================================================
./codes/main.py FAILED
------------------------------------------------------------
Failures:
  <NO_OTHER_FAILURES>
------------------------------------------------------------
Root Cause (first observed failure):
[0]:
  time      : 2024-04-23_04:45:28
  host      : instance-20240412-000620.us-central1-a.c.ccm-columbia.internal
  rank      : 1 (local_rank: 1)
  exitcode  : 1 (pid: 1974124)
  error_file: <N/A>
  traceback : To enable traceback see: https://pytorch.org/docs/stable/elastic/errors.html
============================================================
